Workbook

Sheet Sobre
B2: Controle de Chamados - Portfólio de TI
B3: Projeto de portfólio para as áreas de Help Desk, QA e RPA
B6: Este arquivo simula um sistema real de controle de chamados/incidentes de suporte técnico.
B7: Foi criado como projeto de portfólio para demonstrar habilidades de Excel aplicadas a
B8: processos de Help Desk, QA e RPA.
B10: Abas do arquivo:
B11: • Chamados: base de dados com 48 chamados fictícios e fórmulas de apoio
B12: • Parâmetros: tabelas de responsáveis e SLA por prioridade (usadas pelas fórmulas)
B13: • Resumo: indicadores, tabelas-resumo e gráficos
B15: Fórmulas utilizadas: PROCV (VLOOKUP), SE (IF), SOMASES/CONT.SES/MÉDIASES
B16: (SUMIFS/COUNTIFS/AVERAGEIFS), cálculo de diferença entre datas.
B18: Autor: [seu nome aqui]
B19: Data de criação: 26/09/2026

Sheet Chamados
A1: ID Chamado | B1: Data Abertura | C1: Categoria do Problema | D1: Descrição | E1: Prioridade | F1: Status | G1: ID Responsável | H1: Responsável | I1: Data Resolução | J1: Tempo Resolução (dias) | K1: SLA (dias) | L1: Dentro do Prazo
A2: CH028 | B2: 46095 | C2: Rede | D2: Sem acesso à internet | E2: Média | F2: Resolvido | G2: R05 | H2: =VLOOKUP(G2,Parametros!$A$3:$B$7,2,FALSE()) -> Elisa Rocha | I2: 46095 | J2: =IF(I2="","",I2-B2) -> 0 | K2: =VLOOKUP(E2,Parametros!$D$3:$E$6,2,FALSE()) -> 5 | L2: =IF(J2="","",IF(J2<=K2,"Dentro do prazo","Fora do prazo")) -> Dentro do prazo
A3: CH032 | B3: 46095 | C3: Hardware | D3: Monitor não liga | E3: Baixa | F3: Resolvido | G3: R03 | H3: =VLOOKUP(G3,Parametros!$A$3:$B$7,2,FALSE()) -> Carla Mendes | I3: 46104 | J3: =IF(I3="","",I3-B3) -> 9 | K3: =VLOOKUP(E3,Parametros!$D$3:$E$6,2,FALSE()) -> 10 | L3: =IF(J3="","",IF(J3<=K3,"Dentro do prazo","Fora do prazo")) -> Dentro do prazo
A4: CH026 | B4: 46098 | C4: Software | D4: Erro ao abrir sistema ERP | E4: Média | F4: Resolvido | G4: R01 | H4: =VLOOKUP(G4,Parametros!$A$3:$B$7,2,FALSE()) -> Ana Souza | I4: 46103 | J4: =IF(I4="","",I4-B4) -> 5 | K4: =VLOOKUP(E4,Parametros!$D$3:$E$6,2,FALSE()) -> 5 | L4: =IF(J4="","",IF(J4<=K4,"Dentro do prazo","Fora do prazo")) -> Dentro do prazo
A5: CH022 | B5: 46099 | C5: Hardware | D5: Teclado sem funcionar | E5: Média | F5: Resolvido | G5: R02 | H5: =VLOOKUP(G5,Parametros!$A$3:$B$7,2,FALSE()) -> Bruno Lima | I5: 46100 | J5: =IF(I5="","",I5-B5) -> 1 | K5: =VLOOKUP(E5,Parametros!$D$3:$E$6,2,FALSE()) -> 5 | L5: =IF(J5="","",IF(J5<=K5,"Dentro do prazo","Fora do prazo")) -> Dentro do prazo
A6: CH023 | B6: 46100 | C6: Impressora | D6: Fila de impressão travada | E6: Baixa | F6: Resolvido | G6: R01 | H6: =VLOOKUP(G6,Parametros!$A$3:$B$7,2,FALSE()) -> Ana Souza | I6: 46114 | J6: =IF(I6="","",I6-B6) -> 14 | K6: =VLOOKUP(E6,Parametros!$D$3:$E$6,2,FALSE()) -> 10 | L6: =IF(J6="","",IF(J6<=K6,"Dentro do prazo","Fora do prazo")) -> Fora do prazo
A7: CH019 | B7: 46104 | C7: Acesso/Senha | D7: Senha de rede expirada | E7: Baixa | F7: Resolvido | G7: R02 | H7: =VLOOKUP(G7,Parametros!$A$3:$B$7,2,FALSE()) -> Bruno Lima | I7: 46134 | J7: =IF(I7="","",I7-B7) -> 30 | K7: =VLOOKUP(E7,Parametros!$D$3:$E$6,2,FALSE()) -> 10 | L7: =IF(J7="","",IF(J7<=K7,"Dentro do prazo","Fora do prazo")) -> Fora do prazo
A8: CH041 | B8: 46106 | C8: Acesso/Senha | D8: Senha de rede expirada | E8: Média | F8: Resolvido | G8: R03 | H8: =VLOOKUP(G8,Parametros!$A$3:$B$7,2,FALSE()) -> Carla Mendes | I8: 46113 | J8: =IF(I8="","",I8-B8) -> 7 | K8: =VLOOKUP(E8,Parametros!$D$3:$E$6,2,FALSE()) -> 5 | L8: =IF(J8="","",IF(J8<=K8,"Dentro do prazo","Fora do prazo")) -> Fora do prazo
A9: CH034 | B9: 46113 | C9: Rede | D9: Lentidão na rede local | E9: Alta | F9: Cancelado | G9: R02 | H9: =VLOOKUP(G9,Parametros!$A$3:$B$7,2,FALSE()) -> Bruno Lima | I9: 46114 | J9: =IF(I9="","",I9-B9) -> 1 | K9: =VLOOKUP(E9,Parametros!$D$3:$E$6,2,FALSE()) -> 2 | L9: =IF(J9="","",IF(J9<=K9,"Dentro do prazo","Fora do prazo")) -> Dentro do prazo
A10: CH027 | B10: 46118 | C10: Impressora | D10: Erro de driver de impressão | E10: Baixa | F10: Resolvido | G10: R05 | H10: =VLOOKUP(G10,Parametros!$A$3:$B$7,2,FALSE()) -> Elisa Rocha | I10: 46121 | J10: =IF(I10="","",I10-B10) -> 3 | K10: =VLOOKUP(E10,Parametros!$D$3:$E$6,2,FALSE()) -> 10 | L10: =IF(J10="","",IF(J10<=K10,"Dentro do prazo","Fora do prazo")) -> Dentro do prazo
A11: CH038 | B11: 46123 | C11: Rede | D11: Queda de conexão VPN | E11: Alta | F11: Resolvido | G11: R03 | H11: =VLOOKUP(G11,Parametros!$A$3:$B$7,2,FALSE()) -> Carla Mendes | I11: 46124 | J11: =IF(I11="","",I11-B11) -> 1 | K11: =VLOOKUP(E11,Parametros!$D$3:$E$6,2,FALSE()) -> 2 | L11: =IF(J11="","",IF(J11<=K11,"Dentro do prazo","Fora do prazo")) -> Dentro do prazo
A12: CH033 | B12: 46130 | C12: Impressora | D12: Impressora não imprime | E12: Baixa | F12: Em andamento | G12: R05 | H12: =VLOOKUP(G12,Parametros!$A$3:$B$7,2,FALSE()) -> Elisa Rocha | J12: =IF(I12="","",I12-B12) | K12: =VLOOKUP(E12,Parametros!$D$3:$E$6,2,FALSE()) -> 10 | L12: =IF(J12="","",IF(J12<=K12,"Dentro do prazo","Fora do prazo"))
A13: CH031 | B13: 46131 | C13: Hardware | D13: Teclado sem funcionar | E13: Alta | F13: Resolvido | G13: R04 | H13: =VLOOKUP(G13,Parametros!$A$3:$B$7,2,FALSE()) -> Diego Alves | I13: 46136 | J13: =IF(I13="","",I13-B13) -> 5 | K13: =VLOOKUP(E13,Parametros!$D$3:$E$6,2,FALSE()) -> 2 | L13: =IF(J13="","",IF(J13<=K13,"Dentro do prazo","Fora do prazo")) -> Fora do prazo
A14: CH044 | B14: 46136 | C14: Acesso/Senha | D14: Solicitação de reset de senha | E14: Média | F14: Resolvido | G14: R01 | H14: =VLOOKUP(G14,Parametros!$A$3:$B$7,2,FALSE()) -> Ana Souza | I14: 46138 | J14: =IF(I14="","",I14-B14) -> 2 | K14: =VLOOKUP(E14,Parametros!$D$3:$E$6,2,FALSE()) -> 5 | L14: =IF(J14="","",IF(J14<=K14,"Dentro do prazo","Fora do prazo")) -> Dentro do prazo
A15: CH011 | B15: 46137 | C15: Rede | D15: Queda de conexão VPN | E15: Baixa | F15: Resolvido | G15: R05 | H15: =VLOOKUP(G15,Parametros!$A$3:$B$7,2,FALSE()) -> Elisa Rocha | I15: 46147 | J15: =IF(I15="","",I15-B15) -> 10 | K15: =VLOOKUP(E15,Parametros!$D$3:$E$6,2,FALSE()) -> 10 | L15: =IF(J15="","",IF(J15<=K15,"Dentro do prazo","Fora do prazo")) -> Dentro do prazo
A16: CH047 | B16: 46139 | C16: Rede | D16: Lentidão na rede local | E16: Média | F16: Resolvido | G16: R01 | H16: =VLOOKUP(G16,Parametros!$A$3:$B$7,2,FALSE()) -> Ana Souza | I16: 46148 | J16: =IF(I16="","",I16-B16) -> 9 | K16: =VLOOKUP(E16,Parametros!$D$3:$E$6,2,FALSE()) -> 5 | L16: =IF(J16="","",IF(J16<=K16,"Dentro do prazo","Fora do prazo")) -> Fora do prazo
A17: CH001 | B17: 46140 | C17: Rede | D17: Wi-Fi instável | E17: Baixa | F17: Em andamento | G17: R03 | H17: =VLOOKUP(G17,Parametros!$A$3:$B$7,2,FALSE()) -> Carla Mendes | J17: =IF(I17="","",I17-B17) | K17: =VLOOKUP(E17,Parametros!$D$3:$E$6,2,FALSE()) -> 10 | L17: =IF(J17="","",IF(J17<=K17,"Dentro do prazo","Fora do prazo"))
A18: CH010 | B18: 46141 | C18: Hardware | D18: Monitor não liga | E18: Baixa | F18: Resolvido | G18: R03 | H18: =VLOOKUP(G18,Parametros!$A$3:$B$7,2,FALSE()) -> Carla Mendes | I18: 46161 | J18: =IF(I18="","",I18-B18) -> 20 | K18: =VLOOKUP(E18,Parametros!$D$3:$E$6,2,FALSE()) -> 10 | L18: =IF(J18="","",IF(J18<=K18,"Dentro do prazo","Fora do prazo")) -> Fora do prazo
A19: CH045 | B19: 46143 | C19: Hardware | D19: Teclado sem funcionar | E19: Alta | F19: Resolvido | G19: R04 | H19: =VLOOKUP(G19,Parametros!$A$3:$B$7,2,FALSE()) -> Diego Alves | I19: 46148 | J19: =IF(I19="","",I19-B19) -> 5 | K19: =VLOOKUP(E19,Parametros!$D$3:$E$6,2,FALSE()) -> 2 | L19: =IF(J19="","",IF(J19<=K19,"Dentro do prazo","Fora do prazo")) -> Fora do prazo
A20: CH035 | B20: 46149 | C20: Rede | D20: Queda de conexão VPN | E20: Média | F20: Resolvido | G20: R04 | H20: =VLOOKUP(G20,Parametros!$A$3:$B$7,2,FALSE()) -> Diego Alves | I20: 46150 | J20: =IF(I20="","",I20-B20) -> 1 | K20: =VLOOKUP(E20,Parametros!$D$3:$E$6,2,FALSE()) -> 5 | L20: =IF(J20="","",IF(J20<=K20,"Dentro do prazo","Fora do prazo")) -> Dentro do prazo
A21: CH030 | B21: 46150 | C21: Rede | D21: Lentidão na rede local | E21: Baixa | F21: Resolvido | G21: R01 | H21: =VLOOKUP(G21,Parametros!$A$3:$B$7,2,FALSE()) -> Ana Souza | I21: 46168 | J21: =IF(I21="","",I21-B21) -> 18 | K21: =VLOOKUP(E21,Parametros!$D$3:$E$6,2,FALSE()) -> 10 | L21: =IF(J21="","",IF(J21<=K21,"Dentro do prazo","Fora do prazo")) -> Fora do prazo
A22: CH040 | B22: 46152 | C22: Impressora | D22: Fila de impressão travada | E22: Baixa | F22: Resolvido | G22: R01 | H22: =VLOOKUP(G22,Parametros!$A$3:$B$7,2,FALSE()) -> Ana Souza | I22: 46156 | J22: =IF(I22="","",I22-B22) -> 4 | K22: =VLOOKUP(E22,Parametros!$D$3:$E$6,2,FALSE()) -> 10 | L22: =IF(J22="","",IF(J22<=K22,"Dentro do prazo","Fora do prazo")) -> Dentro do prazo
A23: CH036 | B23: 46163 | C23: Software | D23: Licença de software expirada | E23: Baixa | F23: Resolvido | G23: R03 | H23: =VLOOKUP(G23,Parametros!$A$3:$B$7,2,FALSE()) -> Carla Mendes | I23: 46176 | J23: =IF(I23="","",I23-B23) -> 13 | K23: =VLOOKUP(E23,Parametros!$D$3:$E$6,2,FALSE()) -> 10 | L23: =IF(J23="","",IF(J23<=K23,"Dentro do prazo","Fora do prazo")) -> Fora do prazo
A24: CH048 | B24: 46167 | C24: Impressora | D24: Erro de driver de impressão | E24: Baixa | F24: Resolvido | G24: R02 | H24: =VLOOKUP(G24,Parametros!$A$3:$B$7,2,FALSE()) -> Bruno Lima | I24: 46176 | J24: =IF(I24="","",I24-B24) -> 9 | K24: =VLOOKUP(E24,Parametros!$D$3:$E$6,2,FALSE()) -> 10 | L24: =IF(J24="","",IF(J24<=K24,"Dentro do prazo","Fora do prazo")) -> Dentro do prazo
A25: CH005 | B25: 46174 | C25: Acesso/Senha | D25: Senha de rede expirada | E25: Baixa | F25: Resolvido | G25: R04 | H25: =VLOOKUP(G25,Parametros!$A$3:$B$7,2,FALSE()) -> Diego Alves | I25: 46183 | J25: =IF(I25="","",I25-B25) -> 9 | K25: =VLOOKUP(E25,Parametros!$D$3:$E$6,2,FALSE()) -> 10 | L25: =IF(J25="","",IF(J25<=K25,"Dentro do prazo","Fora do prazo")) -> Dentro do prazo
A26: CH043 | B26: 46177 | C26: Rede | D26: Sem acesso à internet | E26: Baixa | F26: Resolvido | G26: R02 | H26: =VLOOKUP(G26,Parametros!$A$3:$B$7,2,FALSE()) -> Bruno Lima | I26: 46179 | J26: =IF(I26="","",I26-B26) -> 2 | K26: =VLOOKUP(E26,Parametros!$D$3:$E$6,2,FALSE()) -> 10 | L26: =IF(J26="","",IF(J26<=K26,"Dentro do prazo","Fora do prazo")) -> Dentro do prazo
A27: CH014 | B27: 46181 | C27: Impressora | D27: Impressora não imprime | E27: Média | F27: Resolvido | G27: R04 | H27: =VLOOKUP(G27,Parametros!$A$3:$B$7,2,FALSE()) -> Diego Alves | I27: 46192 | J27: =IF(I27="","",I27-B27) -> 11 | K27: =VLOOKUP(E27,Parametros!$D$3:$E$6,2,FALSE()) -> 5 | L27: =IF(J27="","",IF(J27<=K27,"Dentro do prazo","Fora do prazo")) -> Fora do prazo
A28: CH021 | B28: 46185 | C28: Impressora | D28: Toner não reconhecido | E28: Crítica | F28: Cancelado | G28: R02 | H28: =VLOOKUP(G28,Parametros!$A$3:$B$7,2,FALSE()) -> Bruno Lima | I28: 46186 | J28: =IF(I28="","",I28-B28) -> 1 | K28: =VLOOKUP(E28,Parametros!$D$3:$E$6,2,FALSE()) -> 1 | L28: =IF(J28="","",IF(J28<=K28,"Dentro do prazo","Fora do prazo")) -> Dentro do prazo
A29: CH025 | B29: 46187 | C29: Hardware | D29: Mouse não é reconhecido | E29: Média | F29: Resolvido | G29: R02 | H29: =VLOOKUP(G29,Parametros!$A$3:$B$7,2,FALSE()) -> Bruno Lima | I29: 46189 | J29: =IF(I29="","",I29-B29) -> 2 | K29: =VLOOKUP(E29,Parametros!$D$3:$E$6,2,FALSE()) -> 5 | L29: =IF(J29="","",IF(J29<=K29,"Dentro do prazo","Fora do prazo")) -> Dentro do prazo
... A31: CH008 | B31: 46199 | C31: Impressora | D31: Toner não reconhecido | E31: Alta | F31: Resolvido | G31: R04 | H31: =VLOOKUP(G31,Parametros!$A$3:$B$7,2,FALSE()) -> Diego Alves | I31: 46200 | J31: =IF(I31="","",I31-B31) -> 1 | K31: =VLOOKUP(E31,Parametros!$D$3:$E$6,2,FALSE()) -> 2 | L31: =IF(J31="","",IF(J31<=K31,"Dentro do prazo","Fora do prazo")) -> Dentro do prazo
A32: CH016 | B32: 46199 | C32: Acesso/Senha | D32: Bloqueio de usuário no AD | E32: Baixa | F32: Aberto | G32: R04 | H32: =VLOOKUP(G32,Parametros!$A$3:$B$7,2,FALSE()) -> Diego Alves | J32: =IF(I32="","",I32-B32) | K32: =VLOOKUP(E32,Parametros!$D$3:$E$6,2,FALSE()) -> 10 | L32: =IF(J32="","",IF(J32<=K32,"Dentro do prazo","Fora do prazo"))
A33: CH013 | B33: 46213 | C33: Hardware | D33: Teclado sem funcionar | E33: Média | F33: Resolvido | G33: R02 | H33: =VLOOKUP(G33,Parametros!$A$3:$B$7,2,FALSE()) -> Bruno Lima | I33: 46218 | J33: =IF(I33="","",I33-B33) -> 5 | K33: =VLOOKUP(E33,Parametros!$D$3:$E$6,2,FALSE()) -> 5 | L33: =IF(J33="","",IF(J33<=K33,"Dentro do prazo","Fora do prazo")) -> Dentro do prazo
A34: CH009 | B34: 46219 | C34: Impressora | D34: Fila de impressão travada | E34: Alta | F34: Resolvido | G34: R01 | H34: =VLOOKUP(G34,Parametros!$A$3:$B$7,2,FALSE()) -> Ana Souza | I34: 46220 | J34: =IF(I34="","",I34-B34) -> 1 | K34: =VLOOKUP(E34,Parametros!$D$3:$E$6,2,FALSE()) -> 2 | L34: =IF(J34="","",IF(J34<=K34,"Dentro do prazo","Fora do prazo")) -> Dentro do prazo
A35: CH037 | B35: 46220 | C35: Hardware | D35: Monitor não liga | E35: Crítica | F35: Resolvido | G35: R01 | H35: =VLOOKUP(G35,Parametros!$A$3:$B$7,2,FALSE()) -> Ana Souza | I35: 46221 | J35: =IF(I35="","",I35-B35) -> 1 | K35: =VLOOKUP(E35,Parametros!$D$3:$E$6,2,FALSE()) -> 1 | L35: =IF(J35="","",IF(J35<=K35,"Dentro do prazo","Fora do prazo")) -> Dentro do prazo
A36: CH024 | B36: 46221 | C36: Impressora | D36: Fila de impressão travada | E36: Baixa | F36: Em andamento | G36: R04 | H36: =VLOOKUP(G36,Parametros!$A$3:$B$7,2,FALSE()) -> Diego Alves | J36: =IF(I36="","",I36-B36) | K36: =VLOOKUP(E36,Parametros!$D$3:$E$6,2,FALSE()) -> 10 | L36: =IF(J36="","",IF(J36<=K36,"Dentro do prazo","Fora do prazo"))
A37: CH020 | B37: 46223 | C37: Hardware | D37: Mouse não é reconhecido | E37: Alta | F37: Resolvido | G37: R02 | H37: =VLOOKUP(G37,Parametros!$A$3:$B$7,2,FALSE()) -> Bruno Lima | I37: 46224 | J37: =IF(I37="","",I37-B37) -> 1 | K37: =VLOOKUP(E37,Parametros!$D$3:$E$6,2,FALSE()) -> 2 | L37: =IF(J37="","",IF(J37<=K37,"Dentro do prazo","Fora do prazo")) -> Dentro do prazo
A38: CH006 | B38: 46224 | C38: Software | D38: Erro ao abrir sistema ERP | E38: Média | F38: Resolvido | G38: R04 | H38: =VLOOKUP(G38,Parametros!$A$3:$B$7,2,FALSE()) -> Diego Alves | I38: 46229 | J38: =IF(I38="","",I38-B38) -> 5 | K38: =VLOOKUP(E38,Parametros!$D$3:$E$6,2,FALSE()) -> 5 | L38: =IF(J38="","",IF(J38<=K38,"Dentro do prazo","Fora do prazo")) -> Dentro do prazo
A39: CH002 | B39: 46234 | C39: Rede | D39: Sem acesso à internet | E39: Alta | F39: Resolvido | G39: R05 | H39: =VLOOKUP(G39,Parametros!$A$3:$B$7,2,FALSE()) -> Elisa Rocha | I39: 46235 | J39: =IF(I39="","",I39-B39) -> 1 | K39: =VLOOKUP(E39,Parametros!$D$3:$E$6,2,FALSE()) -> 2 | L39: =IF(J39="","",IF(J39<=K39,"Dentro do prazo","Fora do prazo")) -> Dentro do prazo
A40: CH018 | B40: 46236 | C40: Impressora | D40: Impressora não imprime | E40: Média | F40: Resolvido | G40: R02 | H40: =VLOOKUP(G40,Parametros!$A$3:$B$7,2,FALSE()) -> Bruno Lima | I40: 46241 | J40: =IF(I40="","",I40-B40) -> 5 | K40: =VLOOKUP(E40,Parametros!$D$3:$E$6,2,FALSE()) -> 5 | L40: =IF(J40="","",IF(J40<=K40,"Dentro do prazo","Fora do prazo")) -> Dentro do prazo
A41: CH017 | B41: 46243 | C41: Acesso/Senha | D41: Senha de rede expirada | E41: Crítica | F41: Resolvido | G41: R02 | H41: =VLOOKUP(G41,Parametros!$A$3:$B$7,2,FALSE()) -> Bruno Lima | I41: 46244 | J41: =IF(I41="","",I41-B41) -> 1 | K41: =VLOOKUP(E41,Parametros!$D$3:$E$6,2,FALSE()) -> 1 | L41: =IF(J41="","",IF(J41<=K41,"Dentro do prazo","Fora do prazo")) -> Dentro do prazo
...

Sheet Parametros
A1: Responsáveis | D1: SLA por Prioridade
A2: ID | B2: Nome | D2: Prioridade | E2: SLA (dias)
A3: R01 | B3: Ana Souza | D3: Crítica | E3: 1
A4: R02 | B4: Bruno Lima | D4: Alta | E4: 2
A5: R03 | B5: Carla Mendes | D5: Média | E5: 5
A6: R04 | B6: Diego Alves | D6: Baixa | E6: 10
A7: R05 | B7: Elisa Rocha

Sheet Resumo
B2: Resumo e Indicadores de Chamados
B3: Valores calculados automaticamente a partir da aba Chamados
B5: Chamados por Categoria | E5: Chamados por Prioridade | H5: Tempo Médio de Resolução (dias)
B6: Categoria | C6: Quantidade | E6: Prioridade | F6: Quantidade | H6: Prioridade | I6: Tempo Médio
B7: Rede | C7: =COUNTIF(Chamados!$C$2:$C$49,B7) -> 11 | E7: Crítica | F7: =COUNTIF(Chamados!$E$2:$E$49,E7) -> 4 | H7: Crítica | I7: =IFERROR(AVERAGEIFS(Chamados!$J$2:$J$49,Chamados!$E$2:$E$49,H7),0) -> 1
B8: Impressora | C8: =COUNTIF(Chamados!$C$2:$C$49,B8) -> 11 | E8: Alta | F8: =COUNTIF(Chamados!$E$2:$E$49,E8) -> 10 | H8: Alta | I8: =IFERROR(AVERAGEIFS(Chamados!$J$2:$J$49,Chamados!$E$2:$E$49,H8),0) -> 1.9
B9: Acesso/Senha | C9: =COUNTIF(Chamados!$C$2:$C$49,B9) -> 8 | E9: Média | F9: =COUNTIF(Chamados!$E$2:$E$49,E9) -> 14 | H9: Média | I9: =IFERROR(AVERAGEIFS(Chamados!$J$2:$J$49,Chamados!$E$2:$E$49,H9),0) -> 3.9285714
B10: Software | C10: =COUNTIF(Chamados!$C$2:$C$49,B10) -> 5 | E10: Baixa | F10: =COUNTIF(Chamados!$E$2:$E$49,E10) -> 20 | H10: Baixa | I10: =IFERROR(AVERAGEIFS(Chamados!$J$2:$J$49,Chamados!$E$2:$E$49,H10),0) -> 11.266667
B11: Hardware | C11: =COUNTIF(Chamados!$C$2:$C$49,B11) -> 13
B14: Indicadores Gerais
B15: Total de chamados | C15: =COUNTA(Chamados!$A$2:$A$49) -> 48
B16: Chamados resolvidos | C16: =COUNTIF(Chamados!$F$2:$F$49,"Resolvido") -> 41
B17: Chamados em aberto | C17: =COUNTIF(Chamados!$F$2:$F$49,"Aberto")+COUNTIF(Chamados!$F$2:$F$49,"Em andamento") -> 5
B18: Chamados fora do prazo | C18: =COUNTIF(Chamados!$L$2:$L$49,"Fora do prazo") -> 11
